2022-02-21 16:55:41,144 INFO    MainThread:160104 [internal.py:wandb_internal():89] W&B internal server running at pid: 160104, started at: 2022-02-21 16:55:41.144587
2022-02-21 16:55:41,145 DEBUG   HandlerThread:160104 [handler.py:handle_request():131] handle_request: check_version
2022-02-21 16:55:41,145 INFO    WriterThread:160104 [datastore.py:open_for_write():77] open: /home/soroosh/Programmes/DD/DD_package/wandb/run-20220221_165540-1pah92xu/run-1pah92xu.wandb
2022-02-21 16:55:41,146 DEBUG   SenderThread:160104 [sender.py:send():235] send: header
2022-02-21 16:55:41,146 DEBUG   SenderThread:160104 [sender.py:send_request():249] send_request: check_version
2022-02-21 16:55:41,298 DEBUG   SenderThread:160104 [sender.py:send():235] send: run
2022-02-21 16:56:01,176 ERROR   SenderThread:160104 [internal_api.py:execute():143] 409 response executing GraphQL.
2022-02-21 16:56:01,176 ERROR   SenderThread:160104 [internal_api.py:execute():144] {"errors":[{"message":"Error 1062: Duplicate entry '720105-1pah92xu' for key 'PRIMARY'","path":["upsertBucket"]}],"data":{"upsertBucket":null}}
2022-02-21 16:56:01,303 INFO    WriterThread:160104 [datastore.py:close():281] close: /home/soroosh/Programmes/DD/DD_package/wandb/run-20220221_165540-1pah92xu/run-1pah92xu.wandb
2022-02-21 16:56:01,318 INFO    HandlerThread:160104 [handler.py:finish():739] shutting down handler
2022-02-21 16:56:02,169 ERROR   MainThread:160104 [internal.py:wandb_internal():164] Thread SenderThread:
Traceback (most recent call last):
  File "/home/soroosh/venv_Jan2022/lib/python3.9/site-packages/wandb/apis/normalize.py", line 24, in wrapper
    return func(*args, **kwargs)
  File "/home/soroosh/venv_Jan2022/lib/python3.9/site-packages/wandb/sdk/internal/internal_api.py", line 1296, in upsert_run
    response = self.gql(mutation, variable_values=variable_values, **kwargs)
  File "/home/soroosh/venv_Jan2022/lib/python3.9/site-packages/wandb/sdk/lib/retry.py", line 102, in __call__
    result = self._call_fn(*args, **kwargs)
  File "/home/soroosh/venv_Jan2022/lib/python3.9/site-packages/wandb/sdk/internal/internal_api.py", line 146, in execute
    six.reraise(*sys.exc_info())
  File "/home/soroosh/anaconda3/lib/python3.9/site-packages/six.py", line 719, in reraise
    raise value
  File "/home/soroosh/venv_Jan2022/lib/python3.9/site-packages/wandb/sdk/internal/internal_api.py", line 140, in execute
    return self.client.execute(*args, **kwargs)
  File "/home/soroosh/venv_Jan2022/lib/python3.9/site-packages/wandb/vendor/gql-0.2.0/gql/client.py", line 52, in execute
    result = self._get_result(document, *args, **kwargs)
  File "/home/soroosh/venv_Jan2022/lib/python3.9/site-packages/wandb/vendor/gql-0.2.0/gql/client.py", line 60, in _get_result
    return self.transport.execute(document, *args, **kwargs)
  File "/home/soroosh/venv_Jan2022/lib/python3.9/site-packages/wandb/vendor/gql-0.2.0/gql/transport/requests.py", line 39, in execute
    request.raise_for_status()
  File "/home/soroosh/anaconda3/lib/python3.9/site-packages/requests/models.py", line 953, in raise_for_status
    raise HTTPError(http_error_msg, response=self)
requests.exceptions.HTTPError: 409 Client Error: Conflict for url: https://api.wandb.ai/graphql

During handling of the above exception, another exception occurred:

Traceback (most recent call last):
  File "/home/soroosh/venv_Jan2022/lib/python3.9/site-packages/wandb/sdk/internal/internal_util.py", line 54, in run
    self._run()
  File "/home/soroosh/venv_Jan2022/lib/python3.9/site-packages/wandb/sdk/internal/internal_util.py", line 105, in _run
    self._process(record)
  File "/home/soroosh/venv_Jan2022/lib/python3.9/site-packages/wandb/sdk/internal/internal.py", line 305, in _process
    self._sm.send(record)
  File "/home/soroosh/venv_Jan2022/lib/python3.9/site-packages/wandb/sdk/internal/sender.py", line 237, in send
    send_handler(record)
  File "/home/soroosh/venv_Jan2022/lib/python3.9/site-packages/wandb/sdk/internal/sender.py", line 692, in send_run
    self._init_run(run, config_value_dict)
  File "/home/soroosh/venv_Jan2022/lib/python3.9/site-packages/wandb/sdk/internal/sender.py", line 716, in _init_run
    server_run, inserted = self._api.upsert_run(
  File "/home/soroosh/venv_Jan2022/lib/python3.9/site-packages/wandb/apis/normalize.py", line 26, in wrapper
    raise CommError(err.response, err)
wandb.errors.CommError: <Response [409]>
2022-02-21 16:56:04,482 INFO    MainThread:160104 [internal.py:handle_exit():79] Internal process exited
