2022-02-25 14:47:10,771 INFO    MainThread:47089 [internal.py:wandb_internal():89] W&B internal server running at pid: 47089, started at: 2022-02-25 14:47:10.770873
2022-02-25 14:47:10,772 DEBUG   HandlerThread:47089 [handler.py:handle_request():131] handle_request: check_version
2022-02-25 14:47:10,772 INFO    WriterThread:47089 [datastore.py:open_for_write():77] open: /home/soroosh/Programmes/DD/DD_package/wandb/run-20220225_144710-16vq65r8/run-16vq65r8.wandb
2022-02-25 14:47:10,773 DEBUG   SenderThread:47089 [sender.py:send():235] send: header
2022-02-25 14:47:10,773 DEBUG   SenderThread:47089 [sender.py:send_request():249] send_request: check_version
2022-02-25 14:47:10,930 DEBUG   SenderThread:47089 [sender.py:send():235] send: run
2022-02-25 14:47:12,465 ERROR   SenderThread:47089 [internal_api.py:execute():143] 500 response executing GraphQL.
2022-02-25 14:47:12,465 ERROR   SenderThread:47089 [internal_api.py:execute():144] {"error":"Error 1040: Too many connections"}
2022-02-25 14:47:17,640 ERROR   SenderThread:47089 [internal_api.py:execute():143] 500 response executing GraphQL.
2022-02-25 14:47:17,640 ERROR   SenderThread:47089 [internal_api.py:execute():144] {"error":"Error 1040: Too many connections"}
2022-02-25 14:47:20,718 ERROR   SenderThread:47089 [internal_api.py:execute():143] 500 response executing GraphQL.
2022-02-25 14:47:20,718 ERROR   SenderThread:47089 [internal_api.py:execute():144] {"error":"Error 1040: Too many connections"}
2022-02-25 14:47:20,718 ERROR   SenderThread:47089 [retry.py:__call__():126] Retry attempt failed:
Traceback (most recent call last):
  File "/home/soroosh/venv_Jan2022/lib/python3.9/site-packages/wandb/sdk/lib/retry.py", line 102, in __call__
    result = self._call_fn(*args, **kwargs)
  File "/home/soroosh/venv_Jan2022/lib/python3.9/site-packages/wandb/sdk/internal/internal_api.py", line 146, in execute
    six.reraise(*sys.exc_info())
  File "/home/soroosh/anaconda3/lib/python3.9/site-packages/six.py", line 719, in reraise
    raise value
  File "/home/soroosh/venv_Jan2022/lib/python3.9/site-packages/wandb/sdk/internal/internal_api.py", line 140, in execute
    return self.client.execute(*args, **kwargs)
  File "/home/soroosh/venv_Jan2022/lib/python3.9/site-packages/wandb/vendor/gql-0.2.0/gql/client.py", line 52, in execute
    result = self._get_result(document, *args, **kwargs)
  File "/home/soroosh/venv_Jan2022/lib/python3.9/site-packages/wandb/vendor/gql-0.2.0/gql/client.py", line 60, in _get_result
    return self.transport.execute(document, *args, **kwargs)
  File "/home/soroosh/venv_Jan2022/lib/python3.9/site-packages/wandb/vendor/gql-0.2.0/gql/transport/requests.py", line 39, in execute
    request.raise_for_status()
  File "/home/soroosh/anaconda3/lib/python3.9/site-packages/requests/models.py", line 953, in raise_for_status
    raise HTTPError(http_error_msg, response=self)
requests.exceptions.HTTPError: 500 Server Error: Internal Server Error for url: https://api.wandb.ai/graphql
2022-02-25 14:47:27,699 ERROR   SenderThread:47089 [internal_api.py:execute():143] 500 response executing GraphQL.
2022-02-25 14:47:27,699 ERROR   SenderThread:47089 [internal_api.py:execute():144] {"error":"Error 1040: Too many connections"}
2022-02-25 14:47:39,033 ERROR   SenderThread:47089 [internal_api.py:execute():143] 500 response executing GraphQL.
2022-02-25 14:47:39,034 ERROR   SenderThread:47089 [internal_api.py:execute():144] {"error":"Error 1040: Too many connections"}
2022-02-25 14:47:40,931 DEBUG   HandlerThread:47089 [handler.py:handle_request():131] handle_request: shutdown
2022-02-25 14:47:40,931 INFO    HandlerThread:47089 [handler.py:finish():739] shutting down handler
2022-02-25 14:47:40,935 INFO    WriterThread:47089 [datastore.py:close():281] close: /home/soroosh/Programmes/DD/DD_package/wandb/run-20220225_144710-16vq65r8/run-16vq65r8.wandb
2022-02-25 14:50:15,372 INFO    SenderThread:47089 [dir_watcher.py:__init__():169] watching files in: /home/soroosh/Programmes/DD/DD_package/wandb/run-20220225_144710-16vq65r8/files
2022-02-25 14:50:15,375 INFO    SenderThread:47089 [sender.py:_start_run_threads():809] run started: 16vq65r8 with start time 1645789630
2022-02-25 14:50:15,375 INFO    SenderThread:47089 [sender.py:finish():1075] shutting down sender
2022-02-25 14:50:15,375 INFO    SenderThread:47089 [dir_watcher.py:finish():283] shutting down directory watcher
2022-02-25 14:50:16,372 INFO    SenderThread:47089 [dir_watcher.py:finish():313] scan: /home/soroosh/Programmes/DD/DD_package/wandb/run-20220225_144710-16vq65r8/files
2022-02-25 14:50:16,372 INFO    SenderThread:47089 [dir_watcher.py:finish():327] scan save: /home/soroosh/Programmes/DD/DD_package/wandb/run-20220225_144710-16vq65r8/files/config.yaml config.yaml
2022-02-25 14:50:16,372 INFO    SenderThread:47089 [file_pusher.py:finish():177] shutting down file pusher
2022-02-25 14:50:16,372 INFO    SenderThread:47089 [file_pusher.py:join():182] waiting for file pusher
2022-02-25 14:50:17,062 INFO    Thread-10 :47089 [upload_job.py:push():137] Uploaded file /home/soroosh/Programmes/DD/DD_package/wandb/run-20220225_144710-16vq65r8/files/config.yaml
2022-02-25 14:50:17,599 INFO    MainThread:47089 [internal.py:handle_exit():79] Internal process exited
